[2018-10-22 16:41:01,148] INFO in app: Current systemversion: V.1.0.1
[2018-10-22 16:41:05,735] INFO in app: Index page loaded with no errors
[2018-10-22 16:41:15,683] INFO in app: Search page loaded with no errors
[2018-10-22 16:41:30,510] INFO in app: Search requested on python
[2018-10-22 16:41:37,852] INFO in app: Project 2 loaded with no errors
[2018-10-22 16:41:42,829] INFO in app: Techniques page loaded with no errors.
[2018-10-22 16:41:51,461] ERROR in app: A 404 occured in project/3.
[2018-10-22 16:42:05,097] ERROR in app: A 404 occured.
[2018-10-22 16:42:56,241] INFO in app: Search page loaded with no errors
[2018-10-22 17:06:23,666] ERROR in app: Exception on /list [GET]
Traceback (most recent call last):
  File "/usr/local/lib/python3.6/dist-packages/flask/app.py", line 2292, in wsgi_app
    response = self.full_dispatch_request()
  File "/usr/local/lib/python3.6/dist-packages/flask/app.py", line 1815, in full_dispatch_request
    rv = self.handle_user_exception(e)
  File "/usr/local/lib/python3.6/dist-packages/flask/app.py", line 1718, in handle_user_exception
    reraise(exc_type, exc_value, tb)
  File "/usr/local/lib/python3.6/dist-packages/flask/_compat.py", line 35, in reraise
    raise value
  File "/usr/local/lib/python3.6/dist-packages/flask/app.py", line 1813, in full_dispatch_request
    rv = self.dispatch_request()
  File "/usr/local/lib/python3.6/dist-packages/flask/app.py", line 1799, in dispatch_request
    return self.view_functions[rule.endpoint](**req.view_args)
  File "/mnt/e/Ip/TDP003/projekt/app.py", line 73, in list
    ditem = json.loads(item)
  File "/usr/lib/python3.6/json/__init__.py", line 354, in loads
    return _default_decoder.decode(s)
  File "/usr/lib/python3.6/json/decoder.py", line 339, in decode
    obj, end = self.raw_decode(s, idx=_w(s, 0).end())
  File "/usr/lib/python3.6/json/decoder.py", line 355, in raw_decode
    obj, end = self.scan_once(s, idx)
json.decoder.JSONDecodeError: Expecting ':' delimiter: line 1 column 9 (char 8)
[2018-10-23 13:25:26,478] INFO in app: Current systemversion: V.1.0.1
[2018-10-23 13:25:37,071] ERROR in app: Exception on / [GET]
Traceback (most recent call last):
  File "/usr/local/lib/python3.6/dist-packages/flask/app.py", line 2292, in wsgi_app
    response = self.full_dispatch_request()
  File "/usr/local/lib/python3.6/dist-packages/flask/app.py", line 1815, in full_dispatch_request
    rv = self.handle_user_exception(e)
  File "/usr/local/lib/python3.6/dist-packages/flask/app.py", line 1718, in handle_user_exception
    reraise(exc_type, exc_value, tb)
  File "/usr/local/lib/python3.6/dist-packages/flask/_compat.py", line 35, in reraise
    raise value
  File "/usr/local/lib/python3.6/dist-packages/flask/app.py", line 1813, in full_dispatch_request
    rv = self.dispatch_request()
  File "/usr/local/lib/python3.6/dist-packages/flask/app.py", line 1799, in dispatch_request
    return self.view_functions[rule.endpoint](**req.view_args)
  File "/mnt/e/Ip/TDP003/projekt/app.py", line 30, in index
    projects = dl.get_latest_project(database)
  File "/mnt/e/Ip/TDP003/projekt/datalager.py", line 26, in get_latest_project
    projects = search(db)
  File "/mnt/e/Ip/TDP003/projekt/datalager.py", line 63, in search
    db_ = db.copy()
AttributeError: 'NoneType' object has no attribute 'copy'
[2018-10-23 13:25:37,320] ERROR in app: A 404 occured.
[2018-10-23 13:29:23,459] INFO in app: Current systemversion: V.1.0.1
[2018-10-23 13:29:46,498] INFO in app: Current systemversion: V.1.0.1
[2018-10-23 13:29:50,073] ERROR in app: Exception on / [GET]
Traceback (most recent call last):
  File "/usr/local/lib/python3.6/dist-packages/flask/app.py", line 2292, in wsgi_app
    response = self.full_dispatch_request()
  File "/usr/local/lib/python3.6/dist-packages/flask/app.py", line 1815, in full_dispatch_request
    rv = self.handle_user_exception(e)
  File "/usr/local/lib/python3.6/dist-packages/flask/app.py", line 1718, in handle_user_exception
    reraise(exc_type, exc_value, tb)
  File "/usr/local/lib/python3.6/dist-packages/flask/_compat.py", line 35, in reraise
    raise value
  File "/usr/local/lib/python3.6/dist-packages/flask/app.py", line 1813, in full_dispatch_request
    rv = self.dispatch_request()
  File "/usr/local/lib/python3.6/dist-packages/flask/app.py", line 1799, in dispatch_request
    return self.view_functions[rule.endpoint](**req.view_args)
  File "/mnt/e/Ip/TDP003/projekt/app.py", line 33, in index
    projects = dl.get_latest_project(database)
  File "/mnt/e/Ip/TDP003/projekt/datalager.py", line 26, in get_latest_project
    projects = search(db)
  File "/mnt/e/Ip/TDP003/projekt/datalager.py", line 63, in search
    db_ = db.copy()
AttributeError: 'NoneType' object has no attribute 'copy'
[2018-10-23 13:29:50,082] ERROR in app: Database not found, check name in app.py
[2018-10-23 13:29:50,465] ERROR in app: A 404 occured.
[2018-10-23 13:30:26,553] INFO in app: Current systemversion: V.1.0.1
[2018-10-23 13:30:28,957] ERROR in app: Exception on / [GET]
Traceback (most recent call last):
  File "/usr/local/lib/python3.6/dist-packages/flask/app.py", line 2292, in wsgi_app
    response = self.full_dispatch_request()
  File "/usr/local/lib/python3.6/dist-packages/flask/app.py", line 1815, in full_dispatch_request
    rv = self.handle_user_exception(e)
  File "/usr/local/lib/python3.6/dist-packages/flask/app.py", line 1718, in handle_user_exception
    reraise(exc_type, exc_value, tb)
  File "/usr/local/lib/python3.6/dist-packages/flask/_compat.py", line 35, in reraise
    raise value
  File "/usr/local/lib/python3.6/dist-packages/flask/app.py", line 1813, in full_dispatch_request
    rv = self.dispatch_request()
  File "/usr/local/lib/python3.6/dist-packages/flask/app.py", line 1799, in dispatch_request
    return self.view_functions[rule.endpoint](**req.view_args)
  File "/mnt/e/Ip/TDP003/projekt/app.py", line 33, in index
    projects = dl.get_latest_project(database)
  File "/mnt/e/Ip/TDP003/projekt/datalager.py", line 26, in get_latest_project
    projects = search(db)
  File "/mnt/e/Ip/TDP003/projekt/datalager.py", line 63, in search
    db_ = db.copy()
AttributeError: 'NoneType' object has no attribute 'copy'
[2018-10-23 13:30:28,967] ERROR in app: Database not found, check name in app.py
[2018-10-23 13:30:29,214] ERROR in app: A 404 occured.
[2018-10-23 14:00:46,666] INFO in app: Current systemversion: V.1.0.1
[2018-10-23 14:00:51,220] ERROR in app: A 404 occured.
[2018-10-23 14:00:53,229] INFO in app: Search page loaded with no errors
[2018-10-23 14:00:53,230] ERROR in app: Exception on /search [GET]
Traceback (most recent call last):
  File "/usr/local/lib/python3.6/dist-packages/flask/app.py", line 2292, in wsgi_app
    response = self.full_dispatch_request()
  File "/usr/local/lib/python3.6/dist-packages/flask/app.py", line 1815, in full_dispatch_request
    rv = self.handle_user_exception(e)
  File "/usr/local/lib/python3.6/dist-packages/flask/app.py", line 1718, in handle_user_exception
    reraise(exc_type, exc_value, tb)
  File "/usr/local/lib/python3.6/dist-packages/flask/_compat.py", line 35, in reraise
    raise value
  File "/usr/local/lib/python3.6/dist-packages/flask/app.py", line 1813, in full_dispatch_request
    rv = self.dispatch_request()
  File "/usr/local/lib/python3.6/dist-packages/flask/app.py", line 1799, in dispatch_request
    return self.view_functions[rule.endpoint](**req.view_args)
  File "/mnt/e/Ip/TDP003/projekt/app.py", line 52, in search
    return redirect(url_for('list', result = dl.search(database)))
  File "/mnt/e/Ip/TDP003/projekt/datalager.py", line 63, in search
    db_ = db.copy()
AttributeError: 'NoneType' object has no attribute 'copy'
[2018-10-23 14:00:53,236] ERROR in app: Database not found, check name in app.py
[2018-10-23 14:00:53,637] ERROR in app: A 404 occured.
[2018-10-23 14:01:02,478] INFO in app: Current systemversion: V.1.0.1
[2018-10-23 14:01:04,049] INFO in app: Search page loaded with no errors
[2018-10-23 14:01:04,630] ERROR in app: A 404 occured.
[2018-10-23 14:01:09,170] ERROR in app: Exception on /list [GET]
Traceback (most recent call last):
  File "/usr/local/lib/python3.6/dist-packages/flask/app.py", line 2292, in wsgi_app
    response = self.full_dispatch_request()
  File "/usr/local/lib/python3.6/dist-packages/flask/app.py", line 1815, in full_dispatch_request
    rv = self.handle_user_exception(e)
  File "/usr/local/lib/python3.6/dist-packages/flask/app.py", line 1718, in handle_user_exception
    reraise(exc_type, exc_value, tb)
  File "/usr/local/lib/python3.6/dist-packages/flask/_compat.py", line 35, in reraise
    raise value
  File "/usr/local/lib/python3.6/dist-packages/flask/app.py", line 1813, in full_dispatch_request
    rv = self.dispatch_request()
  File "/usr/local/lib/python3.6/dist-packages/flask/app.py", line 1799, in dispatch_request
    return self.view_functions[rule.endpoint](**req.view_args)
  File "/mnt/e/Ip/TDP003/projekt/app.py", line 78, in list
    ditem = json.loads(item)
  File "/usr/lib/python3.6/json/__init__.py", line 354, in loads
    return _default_decoder.decode(s)
  File "/usr/lib/python3.6/json/decoder.py", line 339, in decode
    obj, end = self.raw_decode(s, idx=_w(s, 0).end())
  File "/usr/lib/python3.6/json/decoder.py", line 355, in raw_decode
    obj, end = self.scan_once(s, idx)
json.decoder.JSONDecodeError: Expecting ':' delimiter: line 1 column 20 (char 19)
[2018-10-23 14:01:09,192] ERROR in app: Database not found, check name in app.py
[2018-10-23 14:01:09,605] ERROR in app: A 404 occured.
[2018-10-23 14:01:13,678] ERROR in app: A 404 occured.
[2018-10-23 14:02:03,349] INFO in app: Current systemversion: V.1.0.1
[2018-10-23 14:02:05,096] INFO in app: Index page loaded with no errors
[2018-10-23 14:02:05,668] ERROR in app: A 404 occured.
[2018-10-23 14:02:06,956] INFO in app: Techniques page loaded with no errors.
[2018-10-23 14:02:07,528] ERROR in app: A 404 occured.
